Workbook

Sheet Sheet1
A1: library | B1: model | C1: lin | D1: rnn | E1: cnn | F1: transf | G1: stat | H1: reg | I1: misc | J1: datasets | K1: count
A2: darts | B2: ARIMA | G2: 1 | J2: 31 | K2: =SUM(C2:I2) -> 1
A3: darts | B3: BlockRNNModel | D3: 1 | J3: 31 | K3: =SUM(C3:I3) -> 1
A4: darts | B4: CatBoostModel | H4: 1 | J4: 30 | K4: =SUM(C4:I4) -> 1
A5: darts | B5: DLinearModel | C5: 1 | J5: 31 | K5: =SUM(C5:I5) -> 1
A6: darts | B6: ExponentialSmoothing | G6: 1 | J6: 31 | K6: =SUM(C6:I6) -> 1
A7: darts | B7: FFT | I7: 1 | J7: 31 | K7: =SUM(C7:I7) -> 1
A8: darts | B8: FourTheta | G8: 1 | J8: 31 | K8: =SUM(C8:I8) -> 1
A9: darts | B9: KalmanForecaster | G9: 1 | J9: 31 | K9: =SUM(C9:I9) -> 1
A10: darts | B10: LightGBMModel | H10: 1 | J10: 31 | K10: =SUM(C10:H10) -> 1
A11: darts | B11: LinearRegressionModel | H11: 1 | J11: 31 | K11: =SUM(C11:I11) -> 1
A12: darts | B12: NBEATSModel | C12: 1 | J12: 31 | K12: =SUM(C12:I12) -> 1
A13: darts | B13: NHiTSModel | C13: 1 | J13: 31 | K13: =SUM(C13:I13) -> 1
A14: darts | B14: NLinearModel | C14: 1 | J14: 31 | K14: =SUM(C14:I14) -> 1
A15: darts | B15: RandomForestModel | H15: 1 | J15: 31 | K15: =SUM(C15:H15) -> 1
A16: darts | B16: RNNModel | D16: 1 | J16: 31 | K16: =SUM(C16:I16) -> 1
A17: darts | B17: SKLearnModel | H17: 1 | J17: 31 | K17: =SUM(C17:I17) -> 1
A18: darts | B18: TCNModel | E18: 1 | J18: 31 | K18: =SUM(C18:I18) -> 1
A19: darts | B19: Theta | G19: 1 | J19: 31 | K19: =SUM(C19:I19) -> 1
A20: darts | B20: TFTModel | F20: 0 | J20: 0 | K20: =SUM(C20:I20) -> 0 | M20: excluded
A21: darts | B21: TiDEModel | C21: 1 | J21: 31 | K21: =SUM(C21:I21) -> 1
A22: darts | B22: TransformerModel | F22: 1 | J22: 31 | K22: =SUM(C22:I22) -> 1
A23: darts | B23: TSMixerModel | C23: 1 | J23: 31 | K23: =SUM(C23:I23) -> 1
A24: darts | B24: XGBModel | H24: 1 | J24: 31 | K24: =SUM(C24:I24) -> 1 | L24: =SUM(K2:K24) -> 22
A25: nf | B25: Autoformer | F25: 1 | J25: 31 | K25: =SUM(C25:I25) -> 1
A26: nf | B26: BiTCN | E26: 1 | J26: 31 | K26: =SUM(C26:I26) -> 1
A27: nf | B27: DeepAR | D27: 1 | J27: 31 | K27: =SUM(C27:I27) -> 1
A28: nf | B28: DeepNPTS | C28: 1 | J28: 31 | K28: =SUM(C28:I28) -> 1
A29: nf | B29: DilatedRNN | D29: 1 | J29: 31 | K29: =SUM(C29:I29) -> 1
A30: nf | B30: DLinear | C30: 1 | J30: 31 | K30: =SUM(C30:I30) -> 1
A31: nf | B31: FEDformer | F31: 1 | J31: 31 | K31: =SUM(C31:I31) -> 1
A32: nf | B32: GRU | D32: 1 | J32: 31 | K32: =SUM(C32:I32) -> 1
A33: nf | B33: Informer | F33: 1 | J33: 31 | K33: =SUM(C33:I33) -> 1
A34: nf | B34: iTransformer | F34: 1 | J34: 31 | K34: =SUM(C34:I34) -> 1
A35: nf | B35: KAN | I35: 1 | J35: 31 | K35: =SUM(C35:I35) -> 1
A36: nf | B36: LSTM | D36: 1 | J36: 31 | K36: =SUM(C36:I36) -> 1
A37: nf | B37: MLP | C37: 1 | J37: 31 | K37: =SUM(C37:I37) -> 1
A38: nf | B38: MLPMultivariate | C38: 1 | J38: 31 | K38: =SUM(C38:I38) -> 1
A39: nf | B39: NBEATS | C39: 1 | J39: 31 | K39: =SUM(C39:I39) -> 1
A40: nf | B40: NBEATSx | C40: 1 | J40: 31 | K40: =SUM(C40:I40) -> 1
...

Sheet Sheet2
A1: library | B1: model | C1: class
A2: darts | B2: ARIMA | C2: =INDEX(Sheet1!C$1:I$1, MATCH(1,Sheet1!C2:I2)) -> stat
A3: darts | B3: BlockRNNModel | C3: =INDEX(Sheet1!C$1:I$1, MATCH(1,Sheet1!C3:I3)) -> rnn
A4: darts | B4: CatBoostModel | C4: =INDEX(Sheet1!C$1:I$1, MATCH(1,Sheet1!C4:I4)) -> reg
A5: darts | B5: DLinearModel | C5: =INDEX(Sheet1!C$1:I$1, MATCH(1,Sheet1!C5:I5)) -> lin
A6: darts | B6: ExponentialSmoothing | C6: =INDEX(Sheet1!C$1:I$1, MATCH(1,Sheet1!C6:I6)) -> stat
A7: darts | B7: FFT | C7: =INDEX(Sheet1!C$1:I$1, MATCH(1,Sheet1!C7:I7)) -> misc
A8: darts | B8: FourTheta | C8: =INDEX(Sheet1!C$1:I$1, MATCH(1,Sheet1!C8:I8)) -> stat
A9: darts | B9: KalmanForecaster | C9: =INDEX(Sheet1!C$1:I$1, MATCH(1,Sheet1!C9:I9)) -> stat
A10: darts | B10: LightGBMModel | C10: =INDEX(Sheet1!C$1:I$1, MATCH(1,Sheet1!C10:I10)) -> reg
A11: darts | B11: LinearRegressionModel | C11: =INDEX(Sheet1!C$1:I$1, MATCH(1,Sheet1!C11:I11)) -> reg
A12: darts | B12: NBEATSModel | C12: =INDEX(Sheet1!C$1:I$1, MATCH(1,Sheet1!C12:I12)) -> lin
A13: darts | B13: NHiTSModel | C13: =INDEX(Sheet1!C$1:I$1, MATCH(1,Sheet1!C13:I13)) -> lin
... A105: skt | B105: ThetaForecaster | C105: =INDEX(Sheet1!C$1:I$1, MATCH(1,Sheet1!C105:I105)) -> stat
A106: stf | B106: ARIMA | C106: =INDEX(Sheet1!C$1:I$1, MATCH(1,Sheet1!C108:I108)) -> stat
A107: stf | B107: AutoARIMA | C107: =INDEX(Sheet1!C$1:I$1, MATCH(1,Sheet1!C109:I109)) -> stat
A108: stf | B108: AutoCES | C108: =INDEX(Sheet1!C$1:I$1, MATCH(1,Sheet1!C110:I110)) -> stat
A109: stf | B109: AutoETS | C109: =INDEX(Sheet1!C$1:I$1, MATCH(1,Sheet1!C111:I111)) -> stat
A110: stf | B110: AutoTBATS | C110: =INDEX(Sheet1!C$1:I$1, MATCH(1,Sheet1!C112:I112)) -> stat
A111: stf | B111: AutoTheta | C111: =INDEX(Sheet1!C$1:I$1, MATCH(1,Sheet1!C113:I113)) -> stat
A112: skx | B112: MeanForecaster | C112: =INDEX(Sheet1!C$1:I$1, MATCH(1,Sheet1!C114:I114)) -> reg
A113: skx | B113: MedianForecaster | C113: =INDEX(Sheet1!C$1:I$1, MATCH(1,Sheet1!C115:I115)) -> reg
A114: skx | B114: reducer | C114: =INDEX(Sheet1!C$1:I$1, MATCH(1,Sheet1!C116:I116)) -> reg
A115: skx | B115: regressor | C115: =INDEX(Sheet1!C$1:I$1, MATCH(1,Sheet1!C117:I117)) -> reg
A116: skx | B116: sklearn | C116: =INDEX(Sheet1!C$1:I$1, MATCH(1,Sheet1!C118:I118)) -> reg
